Workbook
Name Slicer_Product: #N/A
Name Slicer_Sales_Person: #N/A

Sheet input
A2: Total Revenue | C2: Country | D2: Total Revenue | F2: Country | G2: Sum of Boxes Shipped | I2: Country | J2: Total Revenue | K2: Total Boxes Shipped | L2: Avg Shipped Box Value | M2: % of Sales
A3: 6183625 | C3: Australia | D3: 1137367 | F3: Australia | G3: 32647 | I3: Australia | J3: 1137367 | K3: 32647 | L3: =J3/K3 -> 34.838331 | M3: =J3/$A$3 -> 0.18393208 | O3: Country | P3: Sum of Boxes Shipped | R3: Country | S3: Sum of Amount | U3: Country | V3: Sum of Amount | AE3: Country | AF3: Sum of Amount | AM3: Sales Person | AN3: Total Sales | AO3: Total Boxes Shipped | AP3: Total Sales Per Box | AS3: Sales Person | AT3: Total Sales | AU3: Total Boxes Shipped | AV3: Total Sales Per Box | AX3: Sales Person | AY3: Total Sales | AZ3: Total Boxes Shipped
C4: UK | D4: 1051792 | F4: Canada | G4: 31221 | I4: UK | J4: 1051792 | K4: 30265 | L4: =J4/K4 -> 34.752751 | M4: =J4/$A$3 -> 0.17009311 | O4: Choco Coated Almonds | P4: 6464 | R4: 70% Dark Bites | S4: 211610 | U4: Jan | V4: 57113 | AE4: Mon | AF4: 51135 | AM4: Andria Kimpton | AN4: 201747 | AO4: 6448 | AP4: =AN4/AO4 -> 31.288306 | AS4: {=_xlfn._xlws.SORT(AM4:AP28,2,-1)} -> Ches Bonnell | AT4: 320901 | AU4: 7522 | AV4: 42.661659 | AX4: {=_xlfn._xlws.SORT(AM4:AO28,3,-1)} -> Karlen McCaffrey | AY4: 223895 | AZ4: 9658
C5: India | D5: 1045800 | F5: India | G5: 29470 | I5: India | J5: 1045800 | K5: 29470 | L5: =J5/K5 -> 35.486936 | M5: =J5/$A$3 -> 0.1691241 | O5: Almond Choco | P5: 6736 | R5: Caramel Stuffed Bars | S5: 231588 | U5: Feb | V5: 64533 | AE5: Tue | AF5: 65387 | AM5: Barr Faughny | AN5: 258713 | AO5: 6366 | AP5: =AN5/AO5 -> 40.639805 | AS5: Oby Sorrel | AT5: 316645 | AU5: 8608 | AV5: 36.784967 | AX5: Beverie Moffet | AY5: 278922 | AZ5: 9214
A6: Total Boxes Shipped | C6: USA | D6: 1035349 | F6: New Zealand | G6: 26580 | I6: USA | J6: 1035349 | K6: 26824 | L6: =J6/K6 -> 38.59786 | M6: =J6/$A$3 -> 0.16743399 | O6: Baker's Choco Chips | P6: 6998 | R6: Choco Coated Almonds | S6: 241486 | U6: Mar | V6: 39683 | AE6: Wed | AF6: 70343 | AM6: Beverie Moffet | AN6: 278922 | AO6: 9214 | AP6: =AN6/AO6 -> 30.271543 | AS6: Madelene Upcott | AT6: 316099 | AU6: 7279 | AV6: 43.426157 | AX6: Dennison Crosswaite | AY6: 291669 | AZ6: 8767
A7: 177007 | C7: Canada | D7: 962899 | F7: UK | G7: 30265 | I7: Canada | J7: 962899 | K7: 31221 | L7: =J7/K7 -> 30.841389 | M7: =J7/$A$3 -> 0.15571756 | O7: Raspberry Choco | P7: 7115 | R7: Baker's Choco Chips | S7: 249613 | U7: Apr | V7: 29120 | AE7: Thu | AF7: 60711 | AM7: Brien Boise | AN7: 312816 | AO7: 8102 | AP7: =AN7/AO7 -> 38.609726 | AS7: Brien Boise | AT7: 312816 | AU7: 8102 | AV7: 38.609726 | AX7: Kelci Walkden | AY7: 311710 | AZ7: 8702
C8: New Zealand | D8: 950418 | F8: USA | G8: 26824 | I8: New Zealand | J8: 950418 | K8: 26580 | L8: =J8/K8 -> 35.756885 | M8: =J8/$A$3 -> 0.15369917 | O8: Orange Choco | P8: 7732 | R8: Orange Choco | S8: 256144 | U8: May | V8: 17171 | AE8: Fri | AF8: 77266 | AM8: Camilla Castle | AN8: 196616 | AO8: 5374 | AP8: =AN8/AO8 -> 36.586528 | AS8: Kelci Walkden | AT8: 311710 | AU8: 8702 | AV8: 35.820501 | AX8: Oby Sorrel | AY8: 316645 | AZ8: 8608
O9: Fruit & Nut Bars | P9: 7738 | R9: Drinking Coco | S9: 256655 | U9: Jun | V9: 28210 | AM9: Ches Bonnell | AN9: 320901 | AO9: 7522 | AP9: =AN9/AO9 -> 42.661659 | AS9: Van Tuxwell | AT9: 303149 | AU9: 6799 | AV9: 44.587292 | AX9: Brien Boise | AY9: 312816 | AZ9: 8102
A10: Row Labels | I10: {=I2:J8} -> Country | J10: Total Revenue | O10: Organic Choco Syrup | P10: 7749 | R10: Fruit & Nut Bars | S10: 259147 | U10: Jul | V10: 49861 | AM10: Curtice Advani | AN10: 216461 | AO10: 7074 | AP10: =AN10/AO10 -> 30.599519 | AS10: Dennison Crosswaite | AT10: 291669 | AU10: 8767 | AV10: 33.268963 | AX10: Marney O'Breen | AY10: 259742 | AZ10: 8043
A11: Australia | I11: Australia | J11: 1137367 | K11: {=L3:L8} -> 34.838331 | O11: Manuka Honey Choco | P11: 7781 | R11: After Nines | S11: 261331 | U11: Aug | V11: 39151 | AM11: Dennison Crosswaite | AN11: 291669 | AO11: 8767 | AP11: =AN11/AO11 -> 33.268963 | AS11: Beverie Moffet | AT11: 278922 | AU11: 9214 | AV11: 30.271543 | AX11: Jan Morforth | AY11: 219667 | AZ11: 7661
A12: Canada | C12: Country | D12: Total Revenue | F12: Country | G12: Sum of Boxes Shipped | I12: UK | J12: 1051792 | K12: 34.752751 | O12: 85% Dark Bars | P12: 7793 | R12: Raspberry Choco | S12: 264740 | AM12: Dotty Strutley | AN12: 190624 | AO12: 6853 | AP12: =AN12/AO12 -> 27.816139 | AS12: Kaine Padly | AT12: 266490 | AU12: 7253 | AV12: 36.742038 | AX12: Ches Bonnell | AY12: 320901 | AZ12: 7522
A13: India | C13: Jan | D13: 896105 | E13: 0 | F13: Jan | G13: 27535 | I13: India | J13: 1045800 | K13: 35.486936 | O13: 70% Dark Bites | P13: 8015 | R13: Milk Bars | S13: 269248 | AM13: Gigi Bohling | AN13: 232666 | AO13: 6303 | AP13: =AN13/AO13 -> 36.913533 | AS13: Marney O'Breen | AT13: 259742 | AU13: 8043 | AV13: 32.294169 | AX13: Madelene Upcott | AY13: 316099 | AZ13: 7279
A14: New Zealand | C14: Feb | D14: 699377 | E14: =(D14-D13)/D13 -> -0.21953677 | F14: Feb | G14: 18015 | I14: USA | J14: 1035349 | K14: 38.59786 | O14: 99% Dark & Pure | P14: 8127 | R14: Manuka Honey Choco | S14: 275541 | AM14: Gunar Cockshoot | AN14: 238483 | AO14: 6677 | AP14: =AN14/AO14 -> 35.717089 | AS14: Barr Faughny | AT14: 258713 | AU14: 6366 | AV14: 40.639805 | AX14: Kaine Padly | AY14: 266490 | AZ14: 7253
A15: UK | C15: Mar | D15: 749483 | E15: =(D15-D14)/D14 -> 0.071643763 | F15: Mar | G15: 19561 | I15: Canada | J15: 962899 | K15: 30.841389 | O15: Mint Chip Choco | P15: 8207 | R15: Almond Choco | S15: 277536 | AM15: Husein Augar | AN15: 205212 | AO15: 5849 | AP15: =AN15/AO15 -> 35.084972 | AS15: Roddy Speechley | AT15: 251062 | AU15: 6899 | AV15: 36.391071 | AX15: Jehu Rudeforth | AY15: 220976 | AZ15: 7246
A16: USA | C16: Apr | D16: 674051 | E16: =(D16-D15)/D15 -> -0.10064538 | F16: Apr | G16: 21003 | I16: New Zealand | J16: 950418 | K16: 35.756885 | O16: White Choc | P16: 8240 | R16: Mint Chip Choco | S16: 283969 | AM16: Jan Morforth | AN16: 219667 | AO16: 7661 | AP16: =AN16/AO16 -> 28.673411 | AS16: Gunar Cockshoot | AT16: 238483 | AU16: 6677 | AV16: 35.717089 | AX16: Curtice Advani | AY16: 216461 | AZ16: 7074
A17: Grand Total | C17: May | D17: 752892 | E17: =(D17-D16)/D16 -> 0.11696593 | F17: May | G17: 21856 | O17: After Nines | P17: 8257 | R17: Spicy Special Slims | S17: 293454 | AM17: Jehu Rudeforth | AN17: 220976 | AO17: 7246 | AP17: =AN17/AO17 -> 30.496274 | AS17: Gigi Bohling | AT17: 232666 | AU17: 6303 | AV17: 36.913533 | AX17: Roddy Speechley | AY17: 251062 | AZ17: 6899
C18: Jun | D18: 865144 | E18: =(D18-D17)/D17 -> 0.14909443 | F18: Jun | G18: 26260 | O18: Peanut Butter Cubes | P18: 8304 | R18: Organic Choco Syrup | S18: 294700 | AM18: Kaine Padly | AN18: 266490 | AO18: 7253 | AP18: =AN18/AO18 -> 36.742038 | AS18: Karlen McCaffrey | AT18: 223895 | AU18: 9658 | AV18: 23.182336 | AX18: Dotty Strutley | AY18: 190624 | AZ18: 6853
A19: Unique Countries | C19: Jul | D19: 803425 | E19: =(D19-D18)/D18 -> -0.071339569 | F19: Jul | G19: 22876 | O19: Milk Bars | P19: 8330 | R19: 85% Dark Bars | S19: 299229 | AM19: Karlen McCaffrey | AN19: 223895 | AO19: 9658 | AP19: =AN19/AO19 -> 23.182336 | AS19: Jehu Rudeforth | AT19: 220976 | AU19: 7246 | AV19: 30.496274 | AX19: Van Tuxwell | AY19: 303149 | AZ19: 6799
A20: =COUNTA(A11:A16) -> 6 | C20: Aug | D20: 743148 | E20: =(D20-D19)/D19 -> -0.075025049 | F20: Aug | G20: 19901 | O20: Drinking Coco | P20: 8660 | R20: 99% Dark & Pure | S20: 299796 | AM20: Kelci Walkden | AN20: 311710 | AO20: 8702 | AP20: =AN20/AO20 -> 35.820501 | AS20: Jan Morforth | AT20: 219667 | AU20: 7661 | AV20: 28.673411 | AX20: Gunar Cockshoot | AY20: 238483 | AZ20: 6677
O21: Spicy Special Slims | P21: 8685 | R21: Eclairs | S21: 312445 | AM21: Madelene Upcott | AN21: 316099 | AO21: 7279 | AP21: =AN21/AO21 -> 43.426157 | AS21: Curtice Advani | AT21: 216461 | AU21: 7074 | AV21: 30.599519 | AX21: Andria Kimpton | AY21: 201747 | AZ21: 6448
A22: Average Box Value | O22: Caramel Stuffed Bars | P22: 8717 | R22: Peanut Butter Cubes | S22: 324842 | AM22: Mallorie Waber | AN22: 200592 | AO22: 5980 | AP22: =AN22/AO22 -> 33.543813 | AS22: Rafaelita Blaksland | AT22: 210245 | AU22: 4297 | AV22: 48.928322 | AX22: Barr Faughny | AY22: 258713 | AZ22: 6366
A23: =GETPIVOTDATA("Amount",$A$2)/GETPIVOTDATA("Boxes Shipped",$A$6) -> 34.934353 | C23: Country | D23: Total Revenue | F23: Country | G23: Sum of Boxes Shipped | O23: Eclairs | P23: 8757 | R23: White Choc | S23: 329147 | AM23: Marney O'Breen | AN23: 259742 | AO23: 8043 | AP23: =AN23/AO23 -> 32.294169 | AS23: Husein Augar | AT23: 205212 | AU23: 5849 | AV23: 35.084972 | AX23: Gigi Bohling | AY23: 232666 | AZ23: 6303
C24: Mon | D24: 1385783 | F24: Mon | G24: 40987 | O24: Smooth Sliky Salty | P24: 8810 | R24: 50% Dark Bites | S24: 341712 | AM24: Oby Sorrel | AN24: 316645 | AO24: 8608 | AP24: =AN24/AO24 -> 36.784967 | AS24: Andria Kimpton | AT24: 201747 | AU24: 6448 | AV24: 31.288306 | AX24: Mallorie Waber | AY24: 200592 | AZ24: 5980
A25: Average of Amount | C25: Tue | D25: 1286719 | F25: Tue | G25: 34068 | O25: 50% Dark Bites | P25: 9792 | R25: Smooth Sliky Salty | S25: 349692 | AM25: Rafaelita Blaksland | AN25: 210245 | AO25: 4297 | AP25: =AN25/AO25 -> 48.928322 | AS25: Mallorie Waber | AT25: 200592 | AU25: 5980 | AV25: 33.543813 | AX25: Husein Augar | AY25: 205212 | AZ25: 5849
A26: 5652.308 | C26: Wed | D26: 1204560 | F26: Wed | G26: 36720 | AM26: Roddy Speechley | AN26: 251062 | AO26: 6899 | AP26: =AN26/AO26 -> 36.391071 | AS26: Camilla Castle | AT26: 196616 | AU26: 5374 | AV26: 36.586528 | AX26: Camilla Castle | AY26: 196616 | AZ26: 5374
C27: Thu | D27: 1244789 | F27: Thu | G27: 32643 | AM27: Van Tuxwell | AN27: 303149 | AO27: 6799 | AP27: =AN27/AO27 -> 44.587292 | AS27: Dotty Strutley | AT27: 190624 | AU27: 6853 | AV27: 27.816139 | AX27: Rafaelita Blaksland | AY27: 210245 | AZ27: 4297
A28: Total Sales Person | C28: Fri | D28: 1061774 | F28: Fri | G28: 32589 | I28: Sum of Amount | J28: Column Labels | AM28: Wilone O'Kielt | AN28: 138523 | AO28: 4033 | AP28: =AN28/AO28 -> 34.347384 | AS28: Wilone O'Kielt | AT28: 138523 | AU28: 4033 | AV28: 34.347384 | AX28: Wilone O'Kielt | AY28: 138523 | AZ28: 4033
A29: =COUNTA(I3:I27) -> 13 | I29: Row Labels | J29: Australia | K29: Canada | L29: India | M29: New Zealand | N29: UK | O29: USA
I30: Smooth Sliky Salty | J30: 0.0073207868 | K30: 0.011038347 | L30: 0.012297156 | M30: 0.006307627 | N30: 0.012230366 | O30: 0.0073570115
A31: Total Products | I31: 50% Dark Bites | J31: 0.014428753 | K31: 0.0072958823 | L31: 0.010438376 | M31: 0.0057076553 | N31: 0.00810075 | O31: 0.0092893731
A32: =COUNTA(O6:O30) -> 22 | I32: White Choc | J32: 0.009280317 | K32: 0.0074543654 | L32: 0.0053182397 | M32: 0.0093595585 | N32: 0.010945521 | O32: 0.010870808 | AM32: Sales Person | AN32: Total Sales
I33: Peanut Butter Cubes | J33: 0.0066393095 | K33: 0.010055752 | L33: 0.012437527 | M33: 0.0050737229 | N33: 0.012888071 | O33: 0.005438234 | AM33: Jan | AN33: 26215 | AS33: Sales Person | AT33: Total Sales
I34: Eclairs | J34: 0.010402151 | K34: 0.0039337767 | L34: 0.012777133 | M34: 0.0097546342 | N34: 0.0063517759 | O34: 0.0073083345 | AM34: Feb | AN34: 9044 | AS34: Australia | AT34: 31934 | AX34: Country | AY34: Sum of Amount
I35: 99% Dark & Pure | J35: 0.0088795812 | K35: 0.0071475874 | L35: 0.0067796802 | M35: 0.0051382482 | N35: 0.012791849 | O35: 0.007745295 | AM35: Mar | AN35: 36925 | AS35: Canada | AT35: 29967 | AX35: Eclairs | AY35: 4515
I36: 85% Dark Bars | J36: 0.0062227253 | K36: 0.0061332956 | L36: 0.0091580586 | M36: 0.010924013 | N36: 0.0067027027 | O36: 0.0092497524 | AM36: Apr | AN36: 13195 | AS36: India | AT36: 30807 | AX36: Mint Chip Choco | AY36: 6139
I37: Organic Choco Syrup | J37: 0.0097750106 | K37: 0.0059238715 | L37: 0.011008915 | M37: 0.0085829914 | N37: 0.0040888637 | O37: 0.0082784774 | AM37: May | AN37: 24171 | AS37: New Zealand | AT37: 40558 | AX37: 99% Dark & Pure | AY37: 7140
I38: Spicy Special Slims | J38: 0.0098655724 | K38: 0.0093878591 | L38: 0.012208858 | M38: 0.0058423659 | N38: 0.0060744305 | O38: 0.0040775435 | AM38: Jun | AN38: 15722 | AS38: UK | AT38: 19831 | AX38: Caramel Stuffed Bars | AY38: 7315
I39: Mint Chip Choco | J39: 0.0081992359 | K39: 0.002514221 | L39: 0.011183246 | M39: 0.014022357 | N39: 0.0041296165 | O39: 0.0058740625 | AM39: Jul | AN39: 37282 | AS39: USA | AT39: 43519 | AX39: Smooth Sliky Salty | AY39: 7406
I40: Almond Choco | J40: 0.0075811518 | K40: 0.0067966605 | L40: 0.0082184803 | M40: 0.0047239281 | N40: 0.009694637 | O40: 0.0078675534 | AM40: Aug | AN40: 34062 | AX40: Orange Choco | AY40: 7770
I41: Manuka Honey Choco | J41: 0.007433989 | K41: 0.0081811235 | L41: 0.0030338192 | M41: 0.0080679213 | N41: 0.0068894863 | O41: 0.010953446 | AX41: Spicy Special Slims | AY41: 12838
...

Sheet Home
C1: 🏠 HOME | E1: | | F1: 🌍GLOBAL INSIGHTS | H1: | | I1: 🍫PRODUCT INSIGHTS | K1: | | L1: 👥 PEOPLE INSIGHTS
F7: TOTAL REVENUE | I7: =input!A3 -> 6183625 | K7: TOTAL BOXES DELIVERED | N7: =input!A7 -> 177007
F10: TOTAL PRODUCTS | I10: =input!A32 -> 22 | K10: REVENUE PER BOX | N10: =input!A23 -> 34.934353
F13: COUNTRIES SERVED | I13: =input!A20 -> 6 | K13: TOTAL SALES PERSONS | N13: =input!A29 -> 13
A19: >> | B19: Australia contributes the highest revenue (18.4%), while the USA has the highest average revenue per box.
A21: >> | B21: The USA generates the highest average revenue per box ($38.60), indicating stronger pricing or a higher sales mix of premium products
A23: >> | B23: Canada ships more boxes than the USA but generates less revenue per box, indicating potential to improve pricing or promote higher-value products.
A25: >> | B25: The variation in average revenue per box across countries suggests different product preferences or pricing strategies by market

Sheet Product Insights
C1: 🏠 HOME | E1: | | F1: 🌍GLOBAL INSIGHTS | H1: | | I1: 🍫PRODUCT INSIGHTS | K1: | | L1: 👥PEOPLE INSIGHTS
A19: Product - Trend Analysis
A30: Revenue Contribution | J30: Boxes Shipped Contribution
A31: Chocolate Products | B31: {=input!J29:O29} -> Australia | C31: Canada | D31: India | E31: New Zealand | F31: UK | G31: USA | H31: Total % | J31: Chocolate Products | K31: {=input!J55:O55} -> Australia | L31: Canada | M31: India | N31: New Zealand | O31: UK | P31: USA | Q31: Total %
A32: {=input!I30:O51} -> Smooth Sliky Salty | B32: 0.0073207868 | C32: 0.011038347 | D32: 0.012297156 | E32: 0.006307627 | F32: 0.012230366 | G32: 0.0073570115 | H32: =SUM(B32:G32) -> 0.056551295 | J32: {=input!I56:O77} -> 50% Dark Bites | K32: 0.01797669 | L32: 0.0038755529 | M32: 0.0069884242 | N32: 0.0053048749 | O32: 0.010976967 | P32: 0.010197337 | Q32: =SUM(K32:P32) -> 0.055319846
A33: 50% Dark Bites | B33: 0.014428753 | C33: 0.0072958823 | D33: 0.010438376 | E33: 0.0057076553 | F33: 0.00810075 | G33: 0.0092893731 | H33: =SUM(B33:G33) -> 0.05526079 | J33: Smooth Sliky Salty | K33: 0.0074912292 | L33: 0.012830001 | M33: 0.0040789347 | N33: 0.0073782393 | O33: 0.010536306 | P33: 0.0074573322 | Q33: =SUM(K33:P33) -> 0.049772043
A34: White Choc | B34: 0.009280317 | C34: 0.0074543654 | D34: 0.0053182397 | E34: 0.0093595585 | F34: 0.010945521 | G34: 0.010870808 | H34: =SUM(B34:G34) -> 0.05322881 | J34: Eclairs | K34: 0.0075194766 | L34: 0.011869587 | M34: 0.011214246 | N34: 0.0050280497 | O34: 0.007191806 | P34: 0.0066494545 | Q34: =SUM(K34:P34) -> 0.04947262
A35: Peanut Butter Cubes | B35: 0.0066393095 | C35: 0.010055752 | D35: 0.012437527 | E35: 0.0050737229 | F35: 0.012888071 | G35: 0.005438234 | H35: =SUM(B35:G35) -> 0.052532616 | J35: Caramel Stuffed Bars | K35: 0.0033557995 | L35: 0.011411978 | M35: 0.0092369228 | N35: 0.0070957646 | O35: 0.012338495 | P35: 0.0058076799 | Q35: =SUM(K35:P35) -> 0.04924664
A36: Eclairs | B36: 0.010402151 | C36: 0.0039337767 | D36: 0.012777133 | E36: 0.0097546342 | F36: 0.0063517759 | G36: 0.0073083345 | H36: =SUM(B36:G36) -> 0.050527805 | J36: Spicy Special Slims | K36: 0.011581463 | L36: 0.0093725107 | M36: 0.011508019 | N36: 0.0049094104 | O36: 0.0038699035 | P36: 0.0078245493 | Q36: =SUM(K36:P36) -> 0.049065856
A37: 99% Dark & Pure | B37: 0.0088795812 | C37: 0.0071475874 | D37: 0.0067796802 | E37: 0.0051382482 | F37: 0.012791849 | G37: 0.007745295 | H37: =SUM(B37:G37) -> 0.048482241 | J37: Drinking Coco | K37: 0.010152141 | L37: 0.011185998 | M37: 0.006220093 | N37: 0.0068528363 | O37: 0.0086493754 | P37: 0.0058641749 | Q37: =SUM(K37:P37) -> 0.048924619
A38: 85% Dark Bars | B38: 0.0062227253 | C38: 0.0061332956 | D38: 0.0091580586 | E38: 0.010924013 | F38: 0.0067027027 | G38: 0.0092497524 | H38: =SUM(B38:G38) -> 0.048390548 | J38: Milk Bars | K38: 0.010287729 | L38: 0.0046834306 | M38: 0.0060393092 | N38: 0.0075420746 | O38: 0.012717011 | P38: 0.0057907314 | Q38: =SUM(K38:P38) -> 0.047060286
A39: Organic Choco Syrup | B39: 0.0097750106 | C39: 0.0059238715 | D39: 0.011008915 | E39: 0.0085829914 | F39: 0.0040888637 | G39: 0.0082784774 | H39: =SUM(B39:G39) -> 0.047658129 | J39: Peanut Butter Cubes | K39: 0.0061410001 | L39: 0.0084290452 | M39: 0.008163519 | N39: 0.010202986 | O39: 0.00714661 | P39: 0.0068302384 | Q39: =SUM(K39:P39) -> 0.046913399
A40: Spicy Special Slims | B40: 0.0098655724 | C40: 0.0093878591 | D40: 0.012208858 | E40: 0.0058423659 | F40: 0.0060744305 | G40: 0.0040775435 | H40: =SUM(B40:G40) -> 0.047456629 | J40: After Nines | K40: 0.0051523386 | L40: 0.007626817 | M40: 0.010587152 | N40: 0.0074347342 | O40: 0.0056438446 | P40: 0.010202986 | Q40: =SUM(K40:P40) -> 0.046647873
A41: Mint Chip Choco | B41: 0.0081992359 | C41: 0.002514221 | D41: 0.011183246 | E41: 0.014022357 | F41: 0.0041296165 | G41: 0.0058740625 | H41: =SUM(B41:G41) -> 0.045922739 | J41: White Choc | K41: 0.0085307361 | L41: 0.0039602954 | M41: 0.0092030259 | N41: 0.007157909 | O41: 0.010897874 | P41: 0.0068019909 | Q41: =SUM(K41:P41) -> 0.046551831
A42: Almond Choco | B42: 0.0075811518 | C42: 0.0067966605 | D42: 0.0082184803 | E42: 0.0047239281 | F42: 0.009694637 | G42: 0.0078675534 | H42: =SUM(B42:G42) -> 0.044882411 | J42: Mint Chip Choco | K42: 0.0060958041 | L42: 0.0061466496 | M42: 0.008564633 | N42: 0.014332767 | O42: 0.0070053727 | P42: 0.0042201721 | Q42: =SUM(K42:P42) -> 0.046365398
A43: Manuka Honey Choco | B43: 0.007433989 | C43: 0.0081811235 | D43: 0.0030338192 | E43: 0.0080679213 | F43: 0.0068894863 | G43: 0.010953446 | H43: =SUM(B43:G43) -> 0.044559785 | J43: 99% Dark & Pure | K43: 0.007626817 | L43: 0.0080618281 | M43: 0.0082200139 | N43: 0.0039941923 | O43: 0.0078866937 | P43: 0.010123893 | Q43: =SUM(K43:P43) -> 0.045913438
A44: Milk Bars | B44: 0.0098927409 | C44: 0.0067479836 | D44: 0.0039145323 | E44: 0.0059600962 | F44: 0.0092237159 | G44: 0.0078030282 | H44: =SUM(B44:G44) -> 0.043542097 | J44: 70% Dark Bites | K44: 0.011880886 | L44: 0.0089149017 | M44: 0.0085363856 | N44: 0.005270978 | O44: 0.0071127131 | P44: 0.0035648308 | Q44: =SUM(K44:P44) -> 0.045280695
... A53: 70% Dark Bites | B53: 0.0063642281 | C53: 0.0095452101 | D53: 0.0056136975 | E53: 0.0060200934 | F53: 0.0033496533 | G53: 0.0033281449 | H53: =SUM(B53:G53) -> 0.034221027 | J53: Choco Coated Almonds | K53: 0.0040563368 | L53: 0.01385256 | M53: 0.0075025281 | N53: 0.0025705198 | O53: 0.006655104 | P53: 0.0018812815 | Q53: =SUM(K53:P53) -> 0.03651833
B54: =SUM(B32:B53) -> 0.18393208 | C54: =SUM(C32:C53) -> 0.15571756 | D54: =SUM(D32:D53) -> 0.1691241 | E54: =SUM(E32:E53) -> 0.15369917 | F54: =SUM(F32:F53) -> 0.17009311 | G54: =SUM(G32:G53) -> 0.16743399 | K54: =SUM(K32:K53) -> 0.18443903 | L54: =SUM(L32:L53) -> 0.17638285 | M54: =SUM(M32:M53) -> 0.16649059 | N54: =SUM(N32:N53) -> 0.15016355 | O54: =SUM(O32:O53) -> 0.17098194 | P54: =SUM(P32:P53) -> 0.15154203

Sheet People Insights
C1: 🏠HOME | E1: | | F1: 🌍 GLOBAL INSIGHTS | H1: | | I1: 🍫PRODUCT INSIGHTS | K1: | | L1: 👥 PEOPLE INSIGHTS
A4: TOP Sales Person | H4: Sales Person - Trend Analysis

Sheet Global Insights
C1: 🏠 HOME | E1: | | F1: 🌍Global insights | H1: | | I1: 🍫PRODUCT INSIGHTS | K1: | | L1: 👥PEOPLE INSIGHTS
O5: {=input!I2:J8} -> Country | P5: Total Revenue | Q5: Business Contribution
O6: Australia | P6: 1137367 | Q6: =P6/SUM($P$6:$P$11) -> 0.18393208
O7: UK | P7: 1051792 | Q7: =P7/SUM($P$6:$P$11) -> 0.17009311
O8: India | P8: 1045800 | Q8: =P8/SUM($P$6:$P$11) -> 0.1691241
O9: USA | P9: 1035349 | Q9: =P9/SUM($P$6:$P$11) -> 0.16743399
O10: Canada | P10: 962899 | Q10: =P10/SUM($P$6:$P$11) -> 0.15571756
O11: New Zealand | P11: 950418 | Q11: =P11/SUM($P$6:$P$11) -> 0.15369917
O13: {=input!I2:I8} -> Country | P13: {=input!K2:K8} -> Total Boxes Shipped | Q13: Business Contribution
O14: Australia | P14: 32647 | Q14: =P14/SUM($P$14:$P$19) -> 0.18443903
O15: UK | P15: 30265 | Q15: =P15/SUM($P$14:$P$19) -> 0.17098194
O16: India | P16: 29470 | Q16: =P16/SUM($P$14:$P$19) -> 0.16649059
O17: USA | P17: 26824 | Q17: =P17/SUM($P$14:$P$19) -> 0.15154203
O18: Canada | P18: 31221 | Q18: =P18/SUM($P$14:$P$19) -> 0.17638285
O19: New Zealand | P19: 26580 | Q19: =P19/SUM($P$14:$P$19) -> 0.15016355
O21: {=input!I2:I8} -> Country | P21: {=input!L2:L8} -> Avg Shipped Box Value | Q21: Business Contribution
O22: Australia | P22: 34.838331 | Q22: =P22/SUM($P$14:$P$19) -> 0.00019681895
O23: UK | P23: 34.752751 | Q23: =P23/SUM($P$14:$P$19) -> 0.00019633546
O24: India | P24: 35.486936 | Q24: =P24/SUM($P$14:$P$19) -> 0.00020048323
O25: USA | P25: 38.59786 | Q25: =P25/SUM($P$14:$P$19) -> 0.00021805838
O26: Canada | P26: 30.841389 | Q26: =P26/SUM($P$14:$P$19) -> 0.00017423824
O27: New Zealand | P27: 35.756885 | Q27: =P27/SUM($P$14:$P$19) -> 0.00020200831

Sheet RAW Data
A1: Sales Person | B1: Country | C1: Product | D1: Week | E1: Month | F1: Amount | G1: Boxes Shipped
A2: Jehu Rudeforth | B2: UK | C2: Mint Chip Choco | D2: Tue | E2: Jan | F2: 5320 | G2: 180
A3: Van Tuxwell | B3: India | C3: 85% Dark Bars | D3: Mon | E3: Aug | F3: 7896 | G3: 94
A4: Gigi Bohling | B4: India | C4: Peanut Butter Cubes | D4: Thu | E4: Jul | F4: 4501 | G4: 91
A5: Jan Morforth | B5: Australia | C5: Peanut Butter Cubes | D5: Wed | E5: Apr | F5: 12726 | G5: 342
A6: Jehu Rudeforth | B6: UK | C6: Peanut Butter Cubes | D6: Thu | E6: Feb | F6: 13685 | G6: 184
A7: Van Tuxwell | B7: India | C7: Smooth Sliky Salty | D7: Mon | E7: Jun | F7: 5376 | G7: 38
A8: Oby Sorrel | B8: UK | C8: 99% Dark & Pure | D8: Tue | E8: Jan | F8: 13685 | G8: 176
A9: Gunar Cockshoot | B9: Australia | C9: After Nines | D9: Thu | E9: Mar | F9: 3080 | G9: 73
A10: Jehu Rudeforth | B10: New Zealand | C10: 50% Dark Bites | D10: Wed | E10: Apr | F10: 3990 | G10: 59
A11: Brien Boise | B11: Australia | C11: 99% Dark & Pure | D11: Mon | E11: Jul | F11: 2835 | G11: 102
A12: Rafaelita Blaksland | B12: UK | C12: Smooth Sliky Salty | D12: Thu | E12: Jan | F12: 4704 | G12: 62
A13: Barr Faughny | B13: USA | C13: Orange Choco | D13: Thu | E13: Mar | F13: 3703 | G13: 11
... A1095: Karlen McCaffrey | B1095: India | C1095: 70% Dark Bites | D1095: Mon | E1095: May | F1095: 5075 | G1095: 344
